{
  "comments": [
    {
      "unresolved": true,
      "key": {
        "uuid": "3266a9f2_c5bb6e30",
        "filename": "/PATCHSET_LEVEL",
        "patchSetId": 7
      },
      "lineNbr": 0,
      "author": {
        "id": 1002131
      },
      "writtenOn": "2025-01-17T03:13:18Z",
      "side": 1,
      "message": "We are still encountering the CI failure.",
      "revId": "20450d5bf3fc8ab95d624a9faf3873cfc2d1033f",
      "serverId": "adbd0a64-1f21-4d83-b585-671fe73cb6e4"
    }
  ]
}