{
  "comments": [
    {
      "unresolved": false,
      "key": {
        "uuid": "b441cae7_e60f00e3",
        "filename": "/PATCHSET_LEVEL",
        "patchSetId": 2
      },
      "lineNbr": 0,
      "author": {
        "id": 1000008
      },
      "writtenOn": "2024-01-18T19:14:09Z",
      "side": 1,
      "message": "not sure why this failed CI but was fine on the last patchset.  And in the original patch set the next commit failed.\n\nI wonder if there is a race condition in CI when multiple run at once.",
      "revId": "478870cf2cbc526571cc39e0d9abe6e7e29319f9",
      "serverId": "adbd0a64-1f21-4d83-b585-671fe73cb6e4"
    }
  ]
}