{
  "comments": [
    {
      "unresolved": false,
      "key": {
        "uuid": "a286b41f_fb66476b",
        "filename": "/PATCHSET_LEVEL",
        "patchSetId": 2
      },
      "lineNbr": 0,
      "author": {
        "id": 1002134
      },
      "writtenOn": "2025-09-30T03:25:08Z",
      "side": 1,
      "message": "Reopen this patch, but the CI appears to have failed for reasons unrelated to the change.",
      "revId": "b11162cab41bb4acf9740a68e86ffc8c9a7fbbac",
      "serverId": "adbd0a64-1f21-4d83-b585-671fe73cb6e4"
    }
  ]
}